Workbook

Sheet BD
A1: Id de registro | B1: Email | C1: Celular | D1: Prioridade | E1: Proprietário | F1: Indústria | G1: # de Pedidos | H1: Canais de vendas | I1: Por onde encontrou? | J1: UTM source | K1: UTM campaing | L1: Data
A2: 198243989630 | B2: hideikolopezmiranda098@gmail.com | C2: 51931386313 | D2: BAJA | E2: 80605720 | F2: Salud y suplementos | G2: No vendo productos aun | H2: WHATSAPP_BUSINESS;SOCIAL_NETWORKS | I2: SOCIAL | J2: PAID_SOCIAL | K2: rmkt_engagers_peru | L2: 1769904015511 | M2: February
A3: 198256320407 | B3: dani.arauco.dlaa@gmail.com | C3: 51922266495 | D3: MEDIA | E3: 80566583 | F3: Alimentos y bebidas | G3: 50 | H3: WHATSAPP_BUSINESS | I3: SOCIAL | J3: SOCIAL_MEDIA | K3: bio | L3: 1769906002163 | M3: February
A4: 142738724660 | B4: silviamazab2016@gmail.com | C4: 51979224856 | D4: BAJA | E4: 80605720 | F4: Otros (libre para escribir) | G4: No vendo productos aun | H4: SOCIAL_NETWORKS;WHATSAPP_BUSINESS | I4: SOCIAL | J4: PAID_SOCIAL | K4: rmkt_engagers_peru | L4: 1769909296051 | M4: February
A5: 198255622519 | B5: valweb@valweb.com.br | C5: 5533998636823 | D5: BAJA | E5: 79360573 | F5: Educación - cursos | G5: 1 a 2 | H5: WHATSAPP_BUSINESS;SOCIAL_NETWORKS;ONLINE_STORE | I5: SOCIAL | J5: DIRECT_TRAFFIC | L5: 1769910521730 | M5: February
A6: 198255475205 | B6: drigofirmino@gmail.com | C6: 5527997799292 | D6: BAJA | E6: 79360573 | F6: Alimentos y bebidas | G6: No vendo productos aun | H6: WHATSAPP_BUSINESS | I6: GOOGLE | J6: DIRECT_TRAFFIC | L6: 1769911231331 | M6: February
A7: 164002674072 | B7: jp_life359@hotmail.com | C7: 51967380067 | D7: SIN DATOS | J7: SOCIAL_MEDIA | L7: 1769912498661 | M7: February
A8: 164002674072 | B8: jp_life359@hotmail.com | C8: 51967380067 | D8: BAJA | E8: 80605720 | F8: Moda, ropa y accesorios | G8: No vendo productos aun | H8: PHYSICAL_STORE;SOCIAL_NETWORKS | I8: SOCIAL | J8: SOCIAL_MEDIA | L8: 1769912667966 | M8: February
A9: 198268556573 | B9: lcasiahome@gmail.com | C9: 51922126304 | D9: BAJA | E9: 80605720 | F9: Hogar y decoración | G9: 1 a 2 | H9: WHATSAPP_BUSINESS;SOCIAL_NETWORKS | I9: SOCIAL | J9: DIRECT_TRAFFIC | L9: 1769913039832 | M9: February
A10: 198271086140 | B10: valfrancisnetwork@gmail.com | C10: 5566996369990 | D10: MEDIA | E10: 79360573 | F10: Otros (libre para escribir) | G10: 3 a 10 | H10: WHATSAPP_BUSINESS | I10: SOCIAL | J10: PAID_SOCIAL | K10: leads_signups_coldaudience_brasil | L10: 1769914305072 | M10: February
A11: 198266616451 | B11: javiermontoyaloyo@live.com | C11: 51995432948 | D11: MEDIA | E11: 80566583 | F11: Hogar y decoración | G11: 1 a 2 | H11: WHATSAPP_BUSINESS;SOCIAL_NETWORKS | I11: SOCIAL | J11: PAID_SOCIAL | K11: rmkt_engagers_peru | L11: 1769916097988 | M11: February
A12: 198273072278 | B12: falecom@lemavos.com.br | C12: 5571999962332 | D12: MEDIA | E12: 79360573 | F12: Alimentos y bebidas | G12: 3 a 10 | H12: WHATSAPP_BUSINESS;ONLINE_STORE;PHYSICAL_STORE | I12: FRIEND | J12: DIRECT_TRAFFIC | L12: 1769916350165 | M12: February
A13: 198270960422 | B13: samyllasilva667@gmail.com | C13: 5599982760066 | D13: BAJA | E13: 79360573 | F13: Otros (libre para escribir) | G13: No vendo productos aun | H13: NONE | I13: SOCIAL | J13: DIRECT_TRAFFIC | L13: 1769917311522 | M13: February
A14: 198281270817 | B14: creyes@rootnutritionsac.com | C14: 51991676367 | D14: BAJA | E14: 80605720 | F14: Salud y suplementos | G14: 50 | H14: SOCIAL_NETWORKS;ONLINE_STORE;WHATSAPP_BUSINESS | I14: SOCIAL | J14: SOCIAL_MEDIA | K14: bio | L14: 1769917774212 | M14: February
A15: 198281559461 | B15: maricelincastellano@gmail.com | C15: 51934918445 | D15: BAJA | E15: 80605720 | F15: Moda, ropa y accesorios | G15: No vendo productos aun | H15: NONE | I15: SOCIAL | J15: PAID_SOCIAL | K15: rmkt_engagers_peru | L15: 1769918709599 | M15: February
A16: 198270960422 | B16: samyllasilva667@gmail.com | C16: 5599982760066 | D16: BAJA | E16: 79360573 | F16: Moda, ropa y accesorios | G16: 1 a 2 | H16: ONLINE_STORE | I16: SOCIAL | J16: DIRECT_TRAFFIC | L16: 1769919080140 | M16: February
A17: 198272911994 | B17: michel@mantaro.pe | C17: 51997686525 | D17: BAJA | E17: 80605720 | F17: Otros (libre para escribir) | G17: No vendo productos aun | H17: WHATSAPP_BUSINESS;SOCIAL_NETWORKS | I17: SOCIAL | J17: PAID_SOCIAL | K17: rmkt_engagers_peru | L17: 1769919100678 | M17: February
A18: 198272936256 | B18: moralesquintanillajennifer@gmail.com | C18: 51918484541 | D18: SIN DATOS | E18: 80605720 | J18: REFERRALS | K18: auth0.yavendio.com/ | L18: 1769919711973 | M18: February
A19: 198276572487 | B19: gabrielantonio1919@hotmail.com | C19: 526624609444 | D19: BAJA | E19: 80605720 | F19: Otros (libre para escribir) | G19: 1 a 2 | H19: WHATSAPP_BUSINESS;SOCIAL_NETWORKS | I19: SOCIAL | J19: PAID_SOCIAL | K19: rmkt_engagers_mexico | L19: 1769921951970 | M19: February
A20: 198278483972 | B20: eavs35@gmail.com | C20: 51943670371 | D20: BAJA | E20: 80605720 | F20: Salud y suplementos | G20: 1 a 2 | H20: WHATSAPP_BUSINESS;SOCIAL_NETWORKS | I20: OTHER | J20: DIRECT_TRAFFIC | L20: 1769922297806 | M20: February
A21: 198283084121 | B21: elcorreodebernales@hotmail.com | C21: 51983483154 | D21: BAJA | E21: 80605720 | F21: Tecnología y gadgets | G21: No vendo productos aun | H21: SOCIAL_NETWORKS | I21: GOOGLE | J21: PAID_SOCIAL | K21: rmkt_engagers_peru | L21: 1769923176641 | M21: February
A22: 198290484371 | B22: pballont@pucp.edu.pe | C22: 51942001716 | D22: BAJA | E22: 80605720 | F22: Moda, ropa y accesorios | G22: No vendo productos aun | H22: WHATSAPP_BUSINESS;SOCIAL_NETWORKS | I22: SOCIAL | J22: DIRECT_TRAFFIC | L22: 1769928969891 | M22: February
A23: 198299135757 | B23: ggh36316@gmail.com | C23: 523315290263 | D23: BAJA | E23: 80605720 | F23: Otros (libre para escribir) | G23: 1 a 2 | H23: PHYSICAL_STORE | I23: SOCIAL | J23: PAID_SOCIAL | K23: rmkt_engagers_mexico | L23: 1769930414668 | M23: February
A24: 198297228298 | B24: fuxchoy@gmail.com | C24: 51944917688 | D24: MEDIA | E24: 80605720 | F24: Moda, ropa y accesorios | G24: 3 a 10 | H24: WHATSAPP_BUSINESS;SOCIAL_NETWORKS;ONLINE_STORE | I24: SOCIAL | J24: DIRECT_TRAFFIC | L24: 1769930802528 | M24: February
A25: 198312079699 | B25: welimarpereiraw@gmail.com | C25: 5534992157506 | D25: BAJA | E25: 79360573 | H25: PHYSICAL_STORE;WHATSAPP_BUSINESS;SOCIAL_NETWORKS;ONLINE_STORE | I25: SOCIAL | J25: DIRECT_TRAFFIC | L25: 1769940988138 | M25: February
A26: 198320959833 | B26: javiercardenasvaldivia@gmail.com | C26: 51942627660 | D26: BAJA | E26: 80605720 | F26: Otros (libre para escribir) | G26: No vendo productos aun | H26: SOCIAL_NETWORKS;WHATSAPP_BUSINESS;PHYSICAL_STORE | I26: SOCIAL | J26: PAID_SOCIAL | K26: rmkt_engagers_peru | L26: 1769943424455 | M26: February
A27: 198322004395 | B27: ladisargon@hotmail.com | C27: 528120734660 | D27: BAJA | E27: 80605720 | F27: Otros (libre para escribir) | G27: 50 | H27: WHATSAPP_BUSINESS;SOCIAL_NETWORKS;ONLINE_STORE | I27: SOCIAL | J27: PAID_SOCIAL | K27: rmkt_webinar_mexico | L27: 1769943594756 | M27: February
A28: 198332342867 | B28: victorfenizola.rj@gmail.com | C28: 5521982446714 | D28: BAJA | E28: 79360573 | F28: Otros (libre para escribir) | G28: No vendo productos aun | H28: WHATSAPP_BUSINESS;SOCIAL_NETWORKS | I28: SOCIAL | J28: DIRECT_TRAFFIC | L28: 1769948403558 | M28: February
A29: 198335997858 | B29: hagisystem@gmail.com | C29: 51934002912 | D29: BAJA | E29: 80605720 | F29: Tecnología y gadgets | G29: 10 a 20 | H29: WHATSAPP_BUSINESS;SOCIAL_NETWORKS;ONLINE_STORE;PHYSICAL_STORE | I29: SOCIAL | J29: PAID_SOCIAL | K29: rmkt_engagers_peru | L29: 1769950099034 | M29: February
A30: 198339064194 | B30: jimenezarantxa44@gmail.com | C30: 51964049675 | D30: BAJA | E30: 80605720 | F30: Mascotas | G30: No vendo productos aun | H30: WHATSAPP_BUSINESS | I30: SOCIAL | J30: PAID_SOCIAL | K30: rmkt_engagers_peru | L30: 1769950835583 | M30: February
A31: 198312079699 | B31: welimarpereiraw@gmail.com | C31: 5534992157506 | D31: BAJA | E31: 79360573 | H31: PHYSICAL_STORE;WHATSAPP_BUSINESS;SOCIAL_NETWORKS;ONLINE_STORE | I31: SOCIAL | J31: DIRECT_TRAFFIC | L31: 1769952714964 | M31: February
A32: 198359606096 | B32: intermdoe@gmail.com | C32: 522381513804 | D32: BAJA | E32: 80605720 | F32: Tecnología y gadgets | G32: 1 a 2 | H32: SOCIAL_NETWORKS | J32: PAID_SOCIAL | K32: rmkt_engagers_mexico | L32: 1769954061502 | M32: February
A33: 198372954752 | B33: hfreyrec@hotmail.com | C33: 51987821794 | D33: BAJA | E33: 80605720 | F33: Educación - cursos | G33: 1 a 2 | H33: NONE | I33: SOCIAL | J33: PAID_SOCIAL | K33: rmkt_engagers_peru | L33: 1769955218701 | M33: February
A34: 198365408091 | B34: dinastiacvida@gmail.com | C34: 523223719779 | D34: BAJA | E34: 80605720 | F34: Alimentos y bebidas | G34: No vendo productos aun | H34: WHATSAPP_BUSINESS;NONE | I34: SOCIAL | J34: PAID_SOCIAL | K34: rmkt_engagers_mexico | L34: 1769955289495 | M34: February
A35: 198364943460 | B35: austenarbildochota@gmail.com | C35: 51900084373 | D35: BAJA | E35: 80605720 | F35: Educación - cursos | G35: No vendo productos aun | H35: WHATSAPP_BUSINESS;SOCIAL_NETWORKS;NONE | I35: PARTNER | J35: PAID_SOCIAL | K35: rmkt_engagers_peru | L35: 1769956143220 | M35: February
A36: 198375156635 | B36: araujogleiciane6@gmail.com | C36: 5562992753805 | D36: SIN DATOS | E36: 79360573 | J36: DIRECT_TRAFFIC | L36: 1769956436329 | M36: February
A37: 186614573466 | B37: yramos@relux.pe | C37: 51930807106 | D37: BAJA | E37: 80605720 | F37: Otros (libre para escribir) | G37: No vendo productos aun | H37: PHYSICAL_STORE | I37: SOCIAL | J37: PAID_SOCIAL | K37: rmkt_engagers_peru | L37: 1769956610524 | M37: February
A38: 198367815567 | B38: carlos.herrerazagazeta@gmail.com | C38: 5541998193312 | D38: BAJA | E38: 79360573 | F38: Productos Belleza y cuidado personal | G38: 1 a 2 | H38: ONLINE_STORE | I38: FRIEND | J38: DIRECT_TRAFFIC | L38: 1769957787463 | M38: February
A39: 198375930882 | B39: manolovalero@live.com.mx | C39: 528713150068 | D39: SIN DATOS | E39: 80605720 | F39: Otros (libre para escribir) | G39: No vendo productos aun | H39: WHATSAPP_BUSINESS;SOCIAL_NETWORKS | I39: SOCIAL | J39: PAID_SOCIAL | K39: rmkt_engagers_mexico | L39: 1769958437066 | M39: February
A40: 197708489753 | B40: euroclub507@gmail.com | C40: 5519920032074 | D40: BAJA | E40: 79360573 | F40: Otros (libre para escribir) | G40: No vendo productos aun | H40: WHATSAPP_BUSINESS | I40: SOCIAL | J40: DIRECT_TRAFFIC | L40: 1769960153868 | M40: February
...

Sheet sources

Sheet sources PQLs

Sheet Resumo
A1: Growth
A2: Mes | B2: February
A3: Días en el mes | B3: =IFERROR(VLOOKUP(B2,AUX!B:C,2,0),0) -> 28
A4: Hoy | B4: =today() -> 46092
B6: LATAM | C6: Brasil | G6: ID
A7: Meta Signups | B7: 1530 | C7: 400 | F7: Luis | G7: 122937812
A8: Meta PQL's | B8: =B7*0.45 -> 688.5 | C8: =C7*0.45 -> 180 | F8: Jorge chu | G8: 85569856
A9: Meta to Date (Signups) | B9: =(B7/$B$3)*day($B$4) -> 601.07143 | C9: =(C7/$B$3)*day($B$4) -> 157.14286 | F9: Pablo | G9: 80566583
A10: Meta to Date (PQL's) | B10: =(B8/$B$3)*day($B$4) -> 270.48214 | C10: =(C8/$B$3)*day($B$4) -> 70.714286 | F10: Rafa | G10: 79360573
F11: Sebas | G11: 1660577231
A12: Signups | B12: =COUNTIFS(BD!E:E,"<>79360573",BD!E:E,"<>Rafaela Garrido") -> 2663 | C12: =COUNTIF(BD!E:E,"79360573") + COUNTIF(BD!E:E,"Rafaela Garrido") -> 753 | F12: Diego | G12: 1626259938
A13: PQL's | B13: =COUNTIFS(BD!D:D,"ALTA",BD!E:E,"<>79360573")+COUNTIFS(BD!D:D,"MEDIA",BD!E:E,"<>79360573") -> 386 | C13: =COUNTIFS(BD!D:D,"ALTA",BD!E:E,"79360573")+COUNTIFS(BD!D:D,"MEDIA",BD!E:E,"79360573") + COUNTIFS(BD!D:D,"ALTA",BD!E:E,"Rafaela Garrido")+COUNTIFS(BD!D:D,"MEDIA",BD!E:E,"Rafaela Garrido") -> 189
A14: Avance del mes (Signups) | B14: =B12/B7 -> 1.7405229 | C14: =C12/C7 -> 1.8825
A15: Avance to Date (Signups) | B15: =B12/B9 -> 4.4304219 | C15: =C12/C9 -> 4.7918182
A16: Avance del mes (PQL's) | B16: =B13/B8 -> 0.56063907 | C16: =C13/C8 -> 1.05
A17: Avance to Date (PQL's) | B17: =B13/B10 -> 1.4270813 | C17: =C13/C10 -> 2.6727273
A19: ="Resumen Diario Marketing Metrics - "&B2&" al "&TEXT(TODAY(),"dd/mm/yyyy")&" Latam - Sign Ups (Real-Meta): "&B12&" de "&B7&" ("&TEXT(B14,"0.0%")&") → Meta To Date: "&TEXT(B9,"0")&" ("&TEXT(B15,"0.0%")&") - PQLs (Real-Meta): "&B13&" de "&B8&" ("&TEXT(B16,"0.0%")&") → Meta To Date: "&TEXT(B10,"0")&" ("&TEXT(B17,"0.0%")&") Sources: "&CHAR(10)&AUX!K2&" Brasil - Sign Ups (Real-Meta): "&C12&" de "&C7&" ("&TEXT(C14,"0.0%")&") → Meta To Date: "&TEXT(C9,"0")&" ("&TEXT(C15,"0.0%")&") - PQLs (Real-Meta): "&C13&" de "&C8&" ("&TEXT(C16,"0.0%")&") → Meta To Date: "&TEXT(C10,"0")&" ("&TEXT(C17,"0.0%")&") Sources: "&CHAR(10)&AUX!L2&" More details in: https://bit.ly/3YrchkM PQL's sources: https://bit.ly/44YJVSJ" -> Resumen Diario Marketing Metrics - February al 11/03/2026 Latam - Sign Ups (Real-Meta): 2663 de 1530 (174.1%) → Meta To Date: 601 (443.0%) - PQLs (Real-Meta): 386 de 688.5 (56.1%) → Meta To Date: 270 (142.7%) Sources: - PAID_SOCIAL: 1598 - SOCIAL_MEDIA: 141 - DIRECT_TRAFFIC: 722 - REFERRALS: 96 - OTHER_CAMPAIGNS: 74 - ORGANIC_SEARCH: 18 - OFFLINE: 5 - Sin fuente: 8 Brasil - Sign Ups (Real-Meta): 753 de 400 (188.3%) → Meta To Date: 157 (479.2%) - PQLs (Real-Meta): 189 de 180 (105.0%) → Meta To Date: 71 (267.3%) Sources: - PAID_SOCIAL: 23 - SOCIAL_MEDIA: 2 - DIRECT_TRAFFIC: 565 - REFERRALS: 38 - OTHER_CAMPAIGNS: 116 - ORGANIC_SEARCH: 7 - OFFLINE: 1 - PAID_SEARCH: 1 More details in: https://bit.ly/3YrchkM PQL's sources: https://bit.ly/44YJVSJ

Sheet AUX
A1: N° Mes | B1: Mes | C1: Días en el mes | E1: Source | F1: LATAM | G1: BR | I1: Texto LATAM | J1: Texto BR | K1: Concat LATAM | L1: Concat BR
A2: 1 | B2: January | C2: =DAY(EOMONTH(DATE(YEAR(TODAY()), MONTH(DATEVALUE(B2 & " 1")), 1), 0)) -> 31 | E2: =IFERROR(__xludf.DUMMYFUNCTION("UNIQUE(FILTER(BD!J:J, BD!J:J<>""UTM source"", BD!J:J<>""""))"),"PAID_SOCIAL") -> PAID_SOCIAL | F2: =IF(E2<>"", COUNTIFS(BD!$J:$J, E2, BD!$E:$E, "<>79360573", BD!$E:$E, "<>Rafaela Garrido"), "") -> 1598 | G2: =IF(E2<>"", COUNTIFS(BD!$J:$J, E2, BD!$E:$E, "79360573") + COUNTIFS(BD!$J:$J, E2, BD!$E:$E, "Rafaela Garrido"), "") -> 23 | I2: =IF(AND(E2<>"", F2>0), " - "&E2&": "&F2&CHAR(10), "") -> - PAID_SOCIAL: 1598 | J2: =IF(AND(E2<>"", G2>0), " - "&E2&": "&G2&CHAR(10), "") -> - PAID_SOCIAL: 23 | K2: =I2&I3&I4&I5&I6&I7&I8&I9&I10&I11&I12&I13&I14&I15&I16&I17&I19 -> - PAID_SOCIAL: 1598 - SOCIAL_MEDIA: 141 - DIRECT_TRAFFIC: 722 - REFERRALS: 96 - OTHER_CAMPAIGNS: 74 - ORGANIC_SEARCH: 18 - OFFLINE: 5 - Sin fuente: 8 | L2: =J2&J3&J4&J5&J6&J7&J8&J9&J10&J11&J12&J13&J14&J15&J16&J17&J19 -> - PAID_SOCIAL: 23 - SOCIAL_MEDIA: 2 - DIRECT_TRAFFIC: 565 - REFERRALS: 38 - OTHER_CAMPAIGNS: 116 - ORGANIC_SEARCH: 7 - OFFLINE: 1 - PAID_SEARCH: 1
A3: =A2+1 -> 2 | B3: February | C3: =DAY(EOMONTH(DATE(YEAR(TODAY()), MONTH(DATEVALUE(B3 & " 1")), 1), 0)) -> 28 | E3: =IFERROR(__xludf.DUMMYFUNCTION("""COMPUTED_VALUE"""),"SOCIAL_MEDIA") -> SOCIAL_MEDIA | F3: =IF(E3<>"", COUNTIFS(BD!$J:$J, E3, BD!$E:$E, "<>79360573", BD!$E:$E, "<>Rafaela Garrido"), "") -> 141 | G3: =IF(E3<>"", COUNTIFS(BD!$J:$J, E3, BD!$E:$E, "79360573") + COUNTIFS(BD!$J:$J, E3, BD!$E:$E, "Rafaela Garrido"), "") -> 2 | I3: =IF(AND(E3<>"", F3>0), " - "&E3&": "&F3&CHAR(10), "") -> - SOCIAL_MEDIA: 141 | J3: =IF(AND(E3<>"", G3>0), " - "&E3&": "&G3&CHAR(10), "") -> - SOCIAL_MEDIA: 2
A4: =A3+1 -> 3 | B4: March | C4: =DAY(EOMONTH(DATE(YEAR(TODAY()), MONTH(DATEVALUE(B4 & " 1")), 1), 0)) -> 31 | E4: =IFERROR(__xludf.DUMMYFUNCTION("""COMPUTED_VALUE"""),"DIRECT_TRAFFIC") -> DIRECT_TRAFFIC | F4: =IF(E4<>"", COUNTIFS(BD!$J:$J, E4, BD!$E:$E, "<>79360573", BD!$E:$E, "<>Rafaela Garrido"), "") -> 722 | G4: =IF(E4<>"", COUNTIFS(BD!$J:$J, E4, BD!$E:$E, "79360573") + COUNTIFS(BD!$J:$J, E4, BD!$E:$E, "Rafaela Garrido"), "") -> 565 | I4: =IF(AND(E4<>"", F4>0), " - "&E4&": "&F4&CHAR(10), "") -> - DIRECT_TRAFFIC: 722 | J4: =IF(AND(E4<>"", G4>0), " - "&E4&": "&G4&CHAR(10), "") -> - DIRECT_TRAFFIC: 565
A5: =A4+1 -> 4 | B5: April | C5: =DAY(EOMONTH(DATE(YEAR(TODAY()), MONTH(DATEVALUE(B5 & " 1")), 1), 0)) -> 30 | E5: =IFERROR(__xludf.DUMMYFUNCTION("""COMPUTED_VALUE"""),"REFERRALS") -> REFERRALS | F5: =IF(E5<>"", COUNTIFS(BD!$J:$J, E5, BD!$E:$E, "<>79360573", BD!$E:$E, "<>Rafaela Garrido"), "") -> 96 | G5: =IF(E5<>"", COUNTIFS(BD!$J:$J, E5, BD!$E:$E, "79360573") + COUNTIFS(BD!$J:$J, E5, BD!$E:$E, "Rafaela Garrido"), "") -> 38 | I5: =IF(AND(E5<>"", F5>0), " - "&E5&": "&F5&CHAR(10), "") -> - REFERRALS: 96 | J5: =IF(AND(E5<>"", G5>0), " - "&E5&": "&G5&CHAR(10), "") -> - REFERRALS: 38
A6: =A5+1 -> 5 | B6: May | C6: =DAY(EOMONTH(DATE(YEAR(TODAY()), MONTH(DATEVALUE(B6 & " 1")), 1), 0)) -> 31 | E6: =IFERROR(__xludf.DUMMYFUNCTION("""COMPUTED_VALUE"""),"OTHER_CAMPAIGNS") -> OTHER_CAMPAIGNS | F6: =IF(E6<>"", COUNTIFS(BD!$J:$J, E6, BD!$E:$E, "<>79360573", BD!$E:$E, "<>Rafaela Garrido"), "") -> 74 | G6: =IF(E6<>"", COUNTIFS(BD!$J:$J, E6, BD!$E:$E, "79360573") + COUNTIFS(BD!$J:$J, E6, BD!$E:$E, "Rafaela Garrido"), "") -> 116 | I6: =IF(AND(E6<>"", F6>0), " - "&E6&": "&F6&CHAR(10), "") -> - OTHER_CAMPAIGNS: 74 | J6: =IF(AND(E6<>"", G6>0), " - "&E6&": "&G6&CHAR(10), "") -> - OTHER_CAMPAIGNS: 116
A7: =A6+1 -> 6 | B7: June | C7: =DAY(EOMONTH(DATE(YEAR(TODAY()), MONTH(DATEVALUE(B7 & " 1")), 1), 0)) -> 30 | E7: =IFERROR(__xludf.DUMMYFUNCTION("""COMPUTED_VALUE"""),"ORGANIC_SEARCH") -> ORGANIC_SEARCH | F7: =IF(E7<>"", COUNTIFS(BD!$J:$J, E7, BD!$E:$E, "<>79360573", BD!$E:$E, "<>Rafaela Garrido"), "") -> 18 | G7: =IF(E7<>"", COUNTIFS(BD!$J:$J, E7, BD!$E:$E, "79360573") + COUNTIFS(BD!$J:$J, E7, BD!$E:$E, "Rafaela Garrido"), "") -> 7 | I7: =IF(AND(E7<>"", F7>0), " - "&E7&": "&F7&CHAR(10), "") -> - ORGANIC_SEARCH: 18 | J7: =IF(AND(E7<>"", G7>0), " - "&E7&": "&G7&CHAR(10), "") -> - ORGANIC_SEARCH: 7
A8: =A7+1 -> 7 | B8: July | C8: =DAY(EOMONTH(DATE(YEAR(TODAY()), MONTH(DATEVALUE(B8 & " 1")), 1), 0)) -> 31 | E8: =IFERROR(__xludf.DUMMYFUNCTION("""COMPUTED_VALUE"""),"OFFLINE") -> OFFLINE | F8: =IF(E8<>"", COUNTIFS(BD!$J:$J, E8, BD!$E:$E, "<>79360573", BD!$E:$E, "<>Rafaela Garrido"), "") -> 5 | G8: =IF(E8<>"", COUNTIFS(BD!$J:$J, E8, BD!$E:$E, "79360573") + COUNTIFS(BD!$J:$J, E8, BD!$E:$E, "Rafaela Garrido"), "") -> 1 | I8: =IF(AND(E8<>"", F8>0), " - "&E8&": "&F8&CHAR(10), "") -> - OFFLINE: 5 | J8: =IF(AND(E8<>"", G8>0), " - "&E8&": "&G8&CHAR(10), "") -> - OFFLINE: 1
A9: =A8+1 -> 8 | B9: August | C9: =DAY(EOMONTH(DATE(YEAR(TODAY()), MONTH(DATEVALUE(B9 & " 1")), 1), 0)) -> 31 | E9: =IFERROR(__xludf.DUMMYFUNCTION("""COMPUTED_VALUE"""),"PAID_SEARCH") -> PAID_SEARCH | F9: =IF(E9<>"", COUNTIFS(BD!$J:$J, E9, BD!$E:$E, "<>79360573", BD!$E:$E, "<>Rafaela Garrido"), "") -> 0 | G9: =IF(E9<>"", COUNTIFS(BD!$J:$J, E9, BD!$E:$E, "79360573") + COUNTIFS(BD!$J:$J, E9, BD!$E:$E, "Rafaela Garrido"), "") -> 1 | I9: =IF(AND(E9<>"", F9>0), " - "&E9&": "&F9&CHAR(10), "") | J9: =IF(AND(E9<>"", G9>0), " - "&E9&": "&G9&CHAR(10), "") -> - PAID_SEARCH: 1
A10: =A9+1 -> 9 | B10: September | C10: =DAY(EOMONTH(DATE(YEAR(TODAY()), MONTH(DATEVALUE(B10 & " 1")), 1), 0)) -> 30 | F10: =IF(E10<>"", COUNTIFS(BD!$J:$J, E10, BD!$E:$E, "<>79360573", BD!$E:$E, "<>Rafaela Garrido"), "") | G10: =IF(E10<>"", COUNTIFS(BD!$J:$J, E10, BD!$E:$E, "79360573") + COUNTIFS(BD!$J:$J, E10, BD!$E:$E, "Rafaela Garrido"), "") | I10: =IF(AND(E10<>"", F10>0), " - "&E10&": "&F10&CHAR(10), "") | J10: =IF(AND(E10<>"", G10>0), " - "&E10&": "&G10&CHAR(10), "")
A11: =A10+1 -> 10 | B11: October | C11: =DAY(EOMONTH(DATE(YEAR(TODAY()), MONTH(DATEVALUE(B11 & " 1")), 1), 0)) -> 31 | F11: =IF(E11<>"", COUNTIFS(BD!$J:$J, E11, BD!$E:$E, "<>79360573", BD!$E:$E, "<>Rafaela Garrido"), "") | G11: =IF(E11<>"", COUNTIFS(BD!$J:$J, E11, BD!$E:$E, "79360573") + COUNTIFS(BD!$J:$J, E11, BD!$E:$E, "Rafaela Garrido"), "") | I11: =IF(AND(E11<>"", F11>0), " - "&E11&": "&F11&CHAR(10), "") | J11: =IF(AND(E11<>"", G11>0), " - "&E11&": "&G11&CHAR(10), "")
A12: =A11+1 -> 11 | B12: November | C12: =DAY(EOMONTH(DATE(YEAR(TODAY()), MONTH(DATEVALUE(B12 & " 1")), 1), 0)) -> 30 | F12: =IF(E12<>"", COUNTIFS(BD!$J:$J, E12, BD!$E:$E, "<>79360573", BD!$E:$E, "<>Rafaela Garrido"), "") | G12: =IF(E12<>"", COUNTIFS(BD!$J:$J, E12, BD!$E:$E, "79360573") + COUNTIFS(BD!$J:$J, E12, BD!$E:$E, "Rafaela Garrido"), "") | I12: =IF(AND(E12<>"", F12>0), " - "&E12&": "&F12&CHAR(10), "") | J12: =IF(AND(E12<>"", G12>0), " - "&E12&": "&G12&CHAR(10), "")
A13: =A12+1 -> 12 | B13: December | C13: =DAY(EOMONTH(DATE(YEAR(TODAY()), MONTH(DATEVALUE(B13 & " 1")), 1), 0)) -> 31 | F13: =IF(E13<>"", COUNTIFS(BD!$J:$J, E13, BD!$E:$E, "<>79360573", BD!$E:$E, "<>Rafaela Garrido"), "") | G13: =IF(E13<>"", COUNTIFS(BD!$J:$J, E13, BD!$E:$E, "79360573") + COUNTIFS(BD!$J:$J, E13, BD!$E:$E, "Rafaela Garrido"), "") | I13: =IF(AND(E13<>"", F13>0), " - "&E13&": "&F13&CHAR(10), "") | J13: =IF(AND(E13<>"", G13>0), " - "&E13&": "&G13&CHAR(10), "")
F14: =IF(E14<>"", COUNTIFS(BD!$J:$J, E14, BD!$E:$E, "<>79360573", BD!$E:$E, "<>Rafaela Garrido"), "") | G14: =IF(E14<>"", COUNTIFS(BD!$J:$J, E14, BD!$E:$E, "79360573") + COUNTIFS(BD!$J:$J, E14, BD!$E:$E, "Rafaela Garrido"), "") | I14: =IF(AND(E14<>"", F14>0), " - "&E14&": "&F14&CHAR(10), "") | J14: =IF(AND(E14<>"", G14>0), " - "&E14&": "&G14&CHAR(10), "")
F15: =IF(E15<>"", COUNTIFS(BD!$J:$J, E15, BD!$E:$E, "<>79360573", BD!$E:$E, "<>Rafaela Garrido"), "") | G15: =IF(E15<>"", COUNTIFS(BD!$J:$J, E15, BD!$E:$E, "79360573") + COUNTIFS(BD!$J:$J, E15, BD!$E:$E, "Rafaela Garrido"), "") | I15: =IF(AND(E15<>"", F15>0), " - "&E15&": "&F15&CHAR(10), "") | J15: =IF(AND(E15<>"", G15>0), " - "&E15&": "&G15&CHAR(10), "")
F16: =IF(E16<>"", COUNTIFS(BD!$J:$J, E16, BD!$E:$E, "<>79360573", BD!$E:$E, "<>Rafaela Garrido"), "") | G16: =IF(E16<>"", COUNTIFS(BD!$J:$J, E16, BD!$E:$E, "79360573") + COUNTIFS(BD!$J:$J, E16, BD!$E:$E, "Rafaela Garrido"), "") | I16: =IF(AND(E16<>"", F16>0), " - "&E16&": "&F16&CHAR(10), "") | J16: =IF(AND(E16<>"", G16>0), " - "&E16&": "&G16&CHAR(10), "")
F17: =IF(E17<>"", COUNTIFS(BD!$J:$J, E17, BD!$E:$E, "<>79360573", BD!$E:$E, "<>Rafaela Garrido"), "") | G17: =IF(E17<>"", COUNTIFS(BD!$J:$J, E17, BD!$E:$E, "79360573") + COUNTIFS(BD!$J:$J, E17, BD!$E:$E, "Rafaela Garrido"), "") | I17: =IF(AND(E17<>"", F17>0), " - "&E17&": "&F17&CHAR(10), "") | J17: =IF(AND(E17<>"", G17>0), " - "&E17&": "&G17&CHAR(10), "")
E19: Sin fuente | F19: =COUNTIFS(BD!J:J, "", BD!E:E, "<>79360573", BD!E:E, "<>Rafaela Garrido", BD!E:E, "<>Proprietário") -> 8 | G19: =COUNTIFS(BD!J:J, "", BD!E:E, "79360573") + COUNTIFS(BD!J:J, "", BD!E:E, "Rafaela Garrido") -> 0 | I19: =IF(F19>0, " - "&E19&": "&F19&CHAR(10), "") -> - Sin fuente: 8 | J19: =IF(G19>0, " - "&E19&": "&G19&CHAR(10), "")
